Workbook

Sheet PROFESSORES
A1: N. Inscr | B1: Nome | C1: Email | D1: Fone | E1: Disciplina | F1: Currículo | G1: Vídeo | H1: Diferencial | I1: Observação | J1: Inglês | L1: Pos Ger | M1: Apr. Ger | N1: Pos Dis | O1: Apr Dis (F) | P1: Dis (L) | Q1: Dis (G) | R1: Dis (A) | S1: Dis (O) | T1: Pos Obj | U1: Apr Obj | V1: OBJ CONT | W1: DISC CONT | X1: FINAL CONT | Y1: SET | Z1: IA | AA1: STATUS | AB1: Q1R | AC1: Q1L | AD1: Q1G | AE1: Q1A | AF1: Q1O | AG1: Q1F | AH1: Q2R | AI1: Q2L | AJ1: Q2G | AK1: Q2A | AL1: Q2O | AM1: Q2F | AN1: Q3R | AO1: Q3L | AP1: Q3G | AQ1: Q3A | AR1: Q3O | AS1: Q3F | AT1: Q4R | AU1: Q4L | AV1: Q4G | AW1: Q4A | AX1: Q4O | AY1: Q4F | BB1: Aferição Constante | BC1: Trabalhos em Grupo | BD1: Seminários | BE1: Devolutiva Individualizada | BF1: Trabalhos de Pesquisa (internet) | BG1: Participação Estimulada | BH1: Estímulo ao Erro | BI1: Filmes e Séries | BJ1: Diagnóstico de Pré-requisitos | BK1: Lousa Interativa | BL1: Análise de resultados por habilidade | BM1: Exercícios frequentes | BN1: Cronômetro / tempo | BO1: Sermões | BP1: Focar nos interessados | BQ1: Destacar erros publicamente | BR1: Corrigir comportamento imperceptível | BS1: Correção pública | BT1: Planejamento de aula | BV1: Empatia | BW1: Presença | BX1: Linguagem | BY1: Preparação | BZ1: Material | CA1: Aferição | CB1: Clareza | CC1: Paciência | CD1: Responsabilidade | CE1: Energia | CF1: Lousa | CG1: Resolução Exercício | CH1: Voz | CI1: Confiança
A2: 0 | B2: Nome do Candidato | C2: emaildocandidato@email.com | D2: 11999999999 | E2: Geografia | F2: https://drive.google.com/open?id=1bMc5VcZVidJfIEMLpSLQu-bXwQ4nvuTp | G2: https://drive.google.com/open?id=11oGrETO_ra2LKFsgtdazGKRuQz0FKj44 | H2: Tive a oportunidade de participar do projeto PIBID, promovido pela CAPES, enquanto estava na minha primeira graduação. | J2: A1-A2 (básico) | L2: 28 | M2: 4.4974138 | N2: 9 | O2: 4.9104167 | P2: 5.6666667 | Q2: 4.4166667 | R2: 4.8333333 | S2: 3.25 | T2: 30 | U2: 4.2058824 | V2: 7 | Y2: EMEFAF | AB2: 1) Uso de material digital (power point) 2) Breve retomada dos conceitos da aula anterior | AC2: 2 | AD2: 4 | AE2: 9 | AF2: 7 | AG2: 4.4 | AH2: 1) Antes de prosseguir com o conteúdo, peço para que três estudantes sintetizem os conceitos mais relevantes da aula anterior 2) Dinâmica com uso de ferramentas lúdicas de aprendizagem (Kahoot, Plickers) 3) Sondagem por meio de avaliações curtas ao longo da unidade letiva | AI2: 24 | AJ2: 15 | AK2: 15 | AL2: 11 | AM2: 18.8 | AN2: 1) Elaboração de resumos em ficha pautada ao térmico de cada módulo e/ou mapas conceituais 2) Realização de listas de exercícios para fixação dos conteúdos | AO2: 14 | AP2: 5 | AQ2: 14 | AR2: 7 | AS2: 11.425 | AT2: Recentemente, tenho aplicado as técnicas ensinadas no livro “Aula Nota 10”, do autor Doug Lemov, às quais têm sido bastante produtivas. | AU2: 28 | AV2: 29 | AW2: 20 | AX2: 14 | AY2: 24.3 | BB2: 3 | BC2: 6 | BD2: 4 | BE2: 0 | BF2: 3 | BG2: 3 | BH2: 12 | BI2: 6 | BJ2: 2 | BK2: 2.5 | BL2: 1.5 | BM2: 2 | BN2: 9 | BO2: 2.5 | BP2: 1 | BQ2: 0.5 | BR2: 3 | BS2: 7.5 | BT2: 3 | BV2: =IFERROR(AVERAGEIF(AULAS_TESTE!$F:$F,$B2,AULAS_TESTE!G:G),"") -> 6.7941176 | BW2: =IFERROR(AVERAGEIF(AULAS_TESTE!$F:$F,$B2,AULAS_TESTE!H:H),"") -> 7.3529412 | BX2: =IFERROR(AVERAGEIF(AULAS_TESTE!$F:$F,$B2,AULAS_TESTE!I:I),"") -> 8.1764706 | BY2: =IFERROR(AVERAGEIF(AULAS_TESTE!$F:$F,$B2,AULAS_TESTE!J:J),"") -> 7.65625 | BZ2: =IFERROR(AVERAGEIF(AULAS_TESTE!$F:$F,$B2,AULAS_TESTE!K:K),"") -> 7.7333333 | CA2: =IFERROR(AVERAGEIF(AULAS_TESTE!$F:$F,$B2,AULAS_TESTE!L:L),"") -> 6.8076923 | CB2: =IFERROR(AVERAGEIF(AULAS_TESTE!$F:$F,$B2,AULAS_TESTE!M:M),"") -> 8.1176471 | CC2: =IFERROR(AVERAGEIF(AULAS_TESTE!$F:$F,$B2,AULAS_TESTE!N:N),"") -> 8.3125 | CD2: =IFERROR(AVERAGEIF(AULAS_TESTE!$F:$F,$B2,AULAS_TESTE!O:O),"") -> 7.5588235 | CE2: =IFERROR(AVERAGEIF(AULAS_TESTE!$F:$F,$B2,AULAS_TESTE!P:P),"") -> 7.6875 | CF2: =IFERROR(AVERAGEIF(AULAS_TESTE!$F:$F,$B2,AULAS_TESTE!Q:Q),"") -> 7.5 | CG2: =IFERROR(AVERAGEIF(AULAS_TESTE!$F:$F,$B2,AULAS_TESTE!R:R),"") -> 6.2727273 | CH2: =IFERROR(AVERAGEIF(AULAS_TESTE!$F:$F,$B2,AULAS_TESTE!S:S),"") -> 8.0625 | CI2: =IFERROR(AVERAGEIF(AULAS_TESTE!$F:$F,$B2,AULAS_TESTE!T:T),"") -> 7.59375
A3: 0 | B3: Nome do Candidato | C3: emaildocandidato@email.com | D3: 11999999999 | E3: Português (Produção e Interpretação de Texto) | F3: https://drive.google.com/open?id=1x0wHCAV_5Oghj-J1hvioPUsxOnDzoxjy | G3: https://drive.google.com/open?id=1ztb4sVW7X9zI-u8fOGhj9YQxmPab7frZ | H3: Sou Marta Maria Ferreira Kagohara, formada em Comunicação Social, Pedagogia e Letras (Português), com duas pós-graduações em Cultura e Produção de Texto e Literatura. Sou mãe de uma filha de 25 anos, casada, e tenho experiência internacional: lecionei por dois anos no Japão, em escolas brasileiras, experiência que me proporcionou uma nova visão de mundo e o enriquecimento de vivências pedagógicas diversas. No Brasil, atuei em empresas na área educacional e, há oito anos e meio, trabalho em sala de aula, experiência que consolidou minha paixão e dedicação à educação. Resido próximo ao centro de Santo André e considero-me resiliente, organizada e de fácil aprendizado. Tenho grande interesse em integrar o quadro docente deste colégio, reconhecido por sua tradição, excelência e comprometimento com a formação de seus alunos, bem como pelo respeito e valorização de seus professores, elementos que considero fundamentais para o pleno desenvolvimento do trabalho pedagógico. Acredito possuir amor pela educação e competências pedagógicas sólidas, e espero contribuir com minha qualificação e experiência, colaborando para o crescimento e a formação integral de crianças e adolescentes. Tenho especial identificação e experiência para atuar com Ensino Fundamental I e II, e estou motivada a participar ativamente do projeto pedagógico desta instituição. | I3: Resposta acima. | J3: A1-A2 (básico) | L3: 31 | M3: 5.162931 | N3: 9 | O3: 5.1020833 | P3: 5.5 | Q3: 3.9166667 | R3: 5.3333333 | S3: 4.75 | T3: 39 | U3: 5.2058824 | Y3: EMEFAF | AB3: Planejo cada aula com objetivos claros e atividades sequenciadas, priorizando metodologias ativas para manter os alunos engajados. Uso recursos visuais e tecnológicos para facilitar a compreensão e monitoro constantemente o ritmo da turma, ajustando quando necessário para garantir aproveitamento do tempo. | AC3: 10 | AD3: 12 | AE3: 15 | AF3: 12 | AG3: 11.525 | AH3: Utilizo avaliações diversificadas, como exercícios escritos, produção de textos, leitura e interpretação, além de atividades orais e debates em sala. Observo o desempenho contínuo dos alunos em atividades práticas e proponho correções imediatas, garantindo que o domínio de habilidades e conceitos seja confirmado ao longo do processo e não apenas em avaliações finais. | AI3: 22 | AJ3: 10 | AK3: 12 | AL3: 15 | AM3: 17.225 | AN3: Ensino técnicas de estudo como organização de resumos, esquemas e mapas conceituais, leitura ativa e anotações estratégicas. Incentivo a gestão do tempo e a revisão periódica do conteúdo, garantindo que os alunos pratiquem essas estratégias em sala e fora dela, para desenvolver autonomia e responsabilidade pelo próprio aprendizado. | AO3: 14 | AP3: 14 | AQ3: 22 | AR3: 16 | AS3: 15.75 | AT3: Renovo minhas práticas pedagógicas participando de cursos de formação continuada, lendo artigos e livros de referência em educação e trocando experiências com colegas. Busco aplicar metodologias ativas e estratégias de ensino centradas no aluno. Entre minhas referências teóricas, destaco Piaget, Vygotsky e Freire, que fundamentam minhas práticas de aprendizagem significativa, desenvolvimento da autonomia e engajamento dos estudantes. | AU3: 20 | AV3: 11 | AW3: 15 | AX3: 14 | AY3: 16.725 | BB3: 9 | BC3: 6 | BD3: 6 | BE3: 0 | BF3: 3 | BG3: 3 | BH3: 9 | BI3: 6 | BJ3: 4 | BK3: 1.5 | BL3: 3 | BM3: 4 | BN3: 3 | BO3: 2 | BP3: 4 | BQ3: 2.5 | BR3: 6 | BS3: 7.5 | BT3: 9 | BV3: =IFERROR(AVERAGEIF(AULAS_TESTE!$F:$F,$B3,AULAS_TESTE!G:G),"") -> 6.7941176 | BW3: =IFERROR(AVERAGEIF(AULAS_TESTE!$F:$F,$B3,AULAS_TESTE!H:H),"") -> 7.3529412 | BX3: =IFERROR(AVERAGEIF(AULAS_TESTE!$F:$F,$B3,AULAS_TESTE!I:I),"") -> 8.1764706 | BY3: =IFERROR(AVERAGEIF(AULAS_TESTE!$F:$F,$B3,AULAS_TESTE!J:J),"") -> 7.65625 | BZ3: =IFERROR(AVERAGEIF(AULAS_TESTE!$F:$F,$B3,AULAS_TESTE!K:K),"") -> 7.7333333 | CA3: =IFERROR(AVERAGEIF(AULAS_TESTE!$F:$F,$B3,AULAS_TESTE!L:L),"") -> 6.8076923 | CB3: =IFERROR(AVERAGEIF(AULAS_TESTE!$F:$F,$B3,AULAS_TESTE!M:M),"") -> 8.1176471 | CC3: =IFERROR(AVERAGEIF(AULAS_TESTE!$F:$F,$B3,AULAS_TESTE!N:N),"") -> 8.3125 | CD3: =IFERROR(AVERAGEIF(AULAS_TESTE!$F:$F,$B3,AULAS_TESTE!O:O),"") -> 7.5588235 | CE3: =IFERROR(AVERAGEIF(AULAS_TESTE!$F:$F,$B3,AULAS_TESTE!P:P),"") -> 7.6875 | CF3: =IFERROR(AVERAGEIF(AULAS_TESTE!$F:$F,$B3,AULAS_TESTE!Q:Q),"") -> 7.5 | CG3: =IFERROR(AVERAGEIF(AULAS_TESTE!$F:$F,$B3,AULAS_TESTE!R:R),"") -> 6.2727273 | CH3: =IFERROR(AVERAGEIF(AULAS_TESTE!$F:$F,$B3,AULAS_TESTE!S:S),"") -> 8.0625 | CI3: =IFERROR(AVERAGEIF(AULAS_TESTE!$F:$F,$B3,AULAS_TESTE!T:T),"") -> 7.59375
A4: 0 | B4: Nome do Candidato | C4: emaildocandidato@email.com | D4: 11999999999 | E4: Português (Literatura) | F4: https://drive.google.com/open?id=1ZGUa46WZ4_1zRe6X8UMa6ywAi__i3GHl | G4: https://drive.google.com/open?id=1mFbQk4RaA4N1gkf2wD9SWheLqt5F3ftm | J4: A1-A2 (básico) | L4: 10 | M4: 4.9275862 | N4: 10 | O4: 2.8666667 | P4: 2.9166667 | Q4: 3.1666667 | R4: 2.75 | S4: 2.5833333 | T4: 9 | U4: 6.3823529 | Y4: EMEFAF | AB4: Antes de cada aula, planejo cuidadosamente o conteúdo, as atividades e os objetivos de aprendizado. Isso ajuda a garantir que o tempo seja utilizado de forma eficiente. | AC4: 7 | AD4: 11 | AE4: 5 | AF4: 8 | AG4: 7.425 | AH4: Utilizar atividades práticas, como projetos, trabalhos em grupo e experimentos, para avaliar a aplicação dos conceitos e habilidades. | AI4: 7 | AJ4: 9 | AK4: 8 | AL4: 6 | AM4: 7.3 | AN4: Ensinar os alunos a resumir e sintetizar informações, ajudando a compreender e reter melhor o conteúdo. | AO4: 8 | AP4: 17 | AQ4: 11 | AR4: 10 | AS4: 10.225 | AT4: Eu Participo de cursos, workshops e seminários para me atualizar sobre novas metodologias e tecnologias educacionais. | AU4: 13 | AV4: 1 | AW4: 9 | AX4: 7 | AY4: 9.45 | BB4: 15 | BC4: 2 | BD4: 2 | BE4: 0 | BF4: 2 | BG4: 4 | BH4: 15 | BI4: 2 | BJ4: 8 | BK4: 0.5 | BL4: 7.5 | BM4: 6 | BN4: 3 | BO4: 2.5 | BP4: 5 | BQ4: 2.5 | BR4: 9 | BS4: 7.5 | BT4: 15 | BV4: =IFERROR(AVERAGEIF(AULAS_TESTE!$F:$F,$B4,AULAS_TESTE!G:G),"") -> 6.7941176 | BW4: =IFERROR(AVERAGEIF(AULAS_TESTE!$F:$F,$B4,AULAS_TESTE!H:H),"") -> 7.3529412 | BX4: =IFERROR(AVERAGEIF(AULAS_TESTE!$F:$F,$B4,AULAS_TESTE!I:I),"") -> 8.1764706 | BY4: =IFERROR(AVERAGEIF(AULAS_TESTE!$F:$F,$B4,AULAS_TESTE!J:J),"") -> 7.65625 | BZ4: =IFERROR(AVERAGEIF(AULAS_TESTE!$F:$F,$B4,AULAS_TESTE!K:K),"") -> 7.7333333 | CA4: =IFERROR(AVERAGEIF(AULAS_TESTE!$F:$F,$B4,AULAS_TESTE!L:L),"") -> 6.8076923 | CB4: =IFERROR(AVERAGEIF(AULAS_TESTE!$F:$F,$B4,AULAS_TESTE!M:M),"") -> 8.1176471 | CC4: =IFERROR(AVERAGEIF(AULAS_TESTE!$F:$F,$B4,AULAS_TESTE!N:N),"") -> 8.3125 | CD4: =IFERROR(AVERAGEIF(AULAS_TESTE!$F:$F,$B4,AULAS_TESTE!O:O),"") -> 7.5588235 | CE4: =IFERROR(AVERAGEIF(AULAS_TESTE!$F:$F,$B4,AULAS_TESTE!P:P),"") -> 7.6875 | CF4: =IFERROR(AVERAGEIF(AULAS_TESTE!$F:$F,$B4,AULAS_TESTE!Q:Q),"") -> 7.5 | CG4: =IFERROR(AVERAGEIF(AULAS_TESTE!$F:$F,$B4,AULAS_TESTE!R:R),"") -> 6.2727273 | CH4: =IFERROR(AVERAGEIF(AULAS_TESTE!$F:$F,$B4,AULAS_TESTE!S:S),"") -> 8.0625 | CI4: =IFERROR(AVERAGEIF(AULAS_TESTE!$F:$F,$B4,AULAS_TESTE!T:T),"") -> 7.59375
A5: 0 | B5: Nome do Candidato | C5: emaildocandidato@email.com | D5: 11999999999 | E5: Matemática | F5: https://drive.google.com/open?id=1d748CJD57UYs1g8OyLgcE63w-mbMcbuz | G5: https://drive.google.com/open?id=1YHfLOmQMLQUPia-_TU3WV2bY7oT-S5Br | H5: Cursos | J5: A1-A2 (básico) | L5: 33 | M5: 4.1508621 | N5: 33 | O5: 1.28125 | P5: 0.83333333 | Q5: 0.41666667 | R5: 2.5833333 | S5: 2 | T5: 32 | U5: 6.1764706 | Y5: EMEFAF | AB5: Uso a criatividade e o dinamismo A matemática descomplicada faz toda diferença na vida do aluno Me preocupo com a aprendizagem da criança e procuro sanar suas dúvidas e medos | AC5: 2 | AD5: 0 | AE5: 3 | AF5: 5 | AG5: 2.4 | AH5: Através de exercícios em sala de aula com atividades práticas Tarefas para casa são também uma ferramenta avaliativa para o professor | AI5: 8 | AJ5: 3 | AK5: 12 | AL5: 5 | AM5: 7.425 | AN5: Conteúdo trabalhado na sua forma mais simples de entendimento Com palavras simples e objetivas para alcançar meu propósito Atividades em sala individuais e duplas Lição de casa Resumo do conteúdo Seminario | AO5: 0 | AP5: 1 | AQ5: 11 | AR5: 8 | AS5: 3.475 | AT5: Trabalho o lúdico e o real Apresentação Seminários Sugestões de pesquisas são bem vindos | AU5: 0 | AV5: 1 | AW5: 5 | AX5: 6 | AY5: 2.075 | BB5: 15 | BC5: 6 | BD5: 2 | BE5: 0 | BF5: 1 | BG5: 2 | BH5: 15 | BI5: 2 | BJ5: 8 | BK5: 1 | BL5: 4.5 | BM5: 10 | BN5: 3 | BO5: 2.5 | BP5: 5 | BQ5: 2.5 | BR5: 3 | BS5: 7.5 | BT5: 15 | BV5: =IFERROR(AVERAGEIF(AULAS_TESTE!$F:$F,$B5,AULAS_TESTE!G:G),"") -> 6.7941176 | BW5: =IFERROR(AVERAGEIF(AULAS_TESTE!$F:$F,$B5,AULAS_TESTE!H:H),"") -> 7.3529412 | BX5: =IFERROR(AVERAGEIF(AULAS_TESTE!$F:$F,$B5,AULAS_TESTE!I:I),"") -> 8.1764706 | BY5: =IFERROR(AVERAGEIF(AULAS_TESTE!$F:$F,$B5,AULAS_TESTE!J:J),"") -> 7.65625 | BZ5: =IFERROR(AVERAGEIF(AULAS_TESTE!$F:$F,$B5,AULAS_TESTE!K:K),"") -> 7.7333333 | CA5: =IFERROR(AVERAGEIF(AULAS_TESTE!$F:$F,$B5,AULAS_TESTE!L:L),"") -> 6.8076923 | CB5: =IFERROR(AVERAGEIF(AULAS_TESTE!$F:$F,$B5,AULAS_TESTE!M:M),"") -> 8.1176471 | CC5: =IFERROR(AVERAGEIF(AULAS_TESTE!$F:$F,$B5,AULAS_TESTE!N:N),"") -> 8.3125 | CD5: =IFERROR(AVERAGEIF(AULAS_TESTE!$F:$F,$B5,AULAS_TESTE!O:O),"") -> 7.5588235 | CE5: =IFERROR(AVERAGEIF(AULAS_TESTE!$F:$F,$B5,AULAS_TESTE!P:P),"") -> 7.6875 | CF5: =IFERROR(AVERAGEIF(AULAS_TESTE!$F:$F,$B5,AULAS_TESTE!Q:Q),"") -> 7.5 | CG5: =IFERROR(AVERAGEIF(AULAS_TESTE!$F:$F,$B5,AULAS_TESTE!R:R),"") -> 6.2727273 | CH5: =IFERROR(AVERAGEIF(AULAS_TESTE!$F:$F,$B5,AULAS_TESTE!S:S),"") -> 8.0625 | CI5: =IFERROR(AVERAGEIF(AULAS_TESTE!$F:$F,$B5,AULAS_TESTE!T:T),"") -> 7.59375
A6: 0 | B6: Nome do Candidato | C6: emaildocandidato@email.com | D6: 11999999999 | E6: Física | F6: https://drive.google.com/open?id=1JRC46tjsYfeGOYxiOH571a8Lo2KU30Gp | G6: https://drive.google.com/open?id=1ZCdS-rvhmyyQLhtXqoduhwfPkFWZGxZF | H6: Meu grande diferencial é que eu possuo uma bagagem em ensino a neuro divergentes, desde casos leves de TDAH até casos mais profundos com o ensino para pessoas com trissomia do 21 e paralisia parcial cerebral | I6: No vídeo, fala que estou na bela vista, mãe para me aproximar dos meus pais que já estão debilitados pela idade, eu me mudei para outro deles. | J6: B1-B2 (intermediário) | L6: 9 | M6: 5.7387931 | N6: 8 | O6: 3.9520833 | P6: 3.8333333 | Q6: 3.1666667 | R6: 4.8333333 | S6: 4.0833333 | T6: 11 | U6: 7 | V6: 5.5 | Y6: EMEFAF | AB6: Utilizo de simulações experimentais e tenho plano de aula pensando na dúvidas que podem aparecer durante a explicação. | AC6: 11 | AD6: 4 | AE6: 12 | AF6: 6 | AG6: 9.25 | AH6: Eu faço avaliações parciais durante o período letivo e faço uma série de perguntas no kahoot para estimular o convencimento. | AI6: 12 | AJ6: 2 | AK6: 8 | AL6: 9 | AM6: 9.275 | AN6: Eu gosto de aplicar a ideia de Feynman, que tenta explicar a física de forma simples e recuperação ativa com testes práticos e peço também para alguns alunos um pouco mais defasados explicarem o que entenderam da matéria. Nunca deixando a modelagem de conceitos físicos, com prática guiada e feedbacks regulares | AO6: 8 | AP6: 29 | AQ6: 24 | AR6: 23 | AS6: 16.575 | AT6: Eu gosto de trazer a tecnologia para a sala, como estamos numa geração no qual a tecnologia de faz presente desde seu nascimento, sinto que quando estamos vendo algo na internet, consigo ter uma atenção geral da sala satisfatória, sempre procuro aperfeiçoar minha lousas, já utilizei o app Miro para acompanhar desenvolvimento de turma em projetos e trabalhos sendo a uma das formas para avaliar o conhecimento prático dos alunos. | AU6: 15 | AV6: 3 | AW6: 14 | AX6: 11 | AY6: 12.325 | BB6: 12 | BC6: 2 | BD6: 4 | BE6: 0 | BF6: 1 | BG6: 5 | BH6: 15 | BI6: 2 | BJ6: 10 | BK6: 1 | BL6: 7.5 | BM6: 10 | BN6: 3 | BO6: 1.5 | BP6: 5 | BQ6: 2.5 | BR6: 15 | BS6: 7.5 | BT6: 15 | BV6: =IFERROR(AVERAGEIF(AULAS_TESTE!$F:$F,$B6,AULAS_TESTE!G:G),"") -> 6.7941176 | BW6: =IFERROR(AVERAGEIF(AULAS_TESTE!$F:$F,$B6,AULAS_TESTE!H:H),"") -> 7.3529412 | BX6: =IFERROR(AVERAGEIF(AULAS_TESTE!$F:$F,$B6,AULAS_TESTE!I:I),"") -> 8.1764706 | BY6: =IFERROR(AVERAGEIF(AULAS_TESTE!$F:$F,$B6,AULAS_TESTE!J:J),"") -> 7.65625 | BZ6: =IFERROR(AVERAGEIF(AULAS_TESTE!$F:$F,$B6,AULAS_TESTE!K:K),"") -> 7.7333333 | CA6: =IFERROR(AVERAGEIF(AULAS_TESTE!$F:$F,$B6,AULAS_TESTE!L:L),"") -> 6.8076923 | CB6: =IFERROR(AVERAGEIF(AULAS_TESTE!$F:$F,$B6,AULAS_TESTE!M:M),"") -> 8.1176471 | CC6: =IFERROR(AVERAGEIF(AULAS_TESTE!$F:$F,$B6,AULAS_TESTE!N:N),"") -> 8.3125 | CD6: =IFERROR(AVERAGEIF(AULAS_TESTE!$F:$F,$B6,AULAS_TESTE!O:O),"") -> 7.5588235 | CE6: =IFERROR(AVERAGEIF(AULAS_TESTE!$F:$F,$B6,AULAS_TESTE!P:P),"") -> 7.6875 | CF6: =IFERROR(AVERAGEIF(AULAS_TESTE!$F:$F,$B6,AULAS_TESTE!Q:Q),"") -> 7.5 | CG6: =IFERROR(AVERAGEIF(AULAS_TESTE!$F:$F,$B6,AULAS_TESTE!R:R),"") -> 6.2727273 | CH6: =IFERROR(AVERAGEIF(AULAS_TESTE!$F:$F,$B6,AULAS_TESTE!S:S),"") -> 8.0625 | CI6: =IFERROR(AVERAGEIF(AULAS_TESTE!$F:$F,$B6,AULAS_TESTE!T:T),"") -> 7.59375
A7: 0 | B7: Nome do Candidato | C7: emaildocandidato@email.com | D7: 11999999999 | E7: Matemática | F7: https://drive.google.com/open?id=1TshXV0s_ZP9rt435hFYfvk9h5Qy3L8X- | G7: https://drive.google.com/open?id=1MvfMsYjqET4jkQs23qWnj4n_bY_SG-It | H7: Palestrar em 3 congressos internacionais com minha pesquisa de mestrado. Ter palestrando 2 vezes na Unicamp, ter dado palestra curso e oficinas na Encontro Hotel Hilbert ( finalistas da OBMEP) Além de ter feito algumas formações e cursos para professores | I7: Gosto de trabalhar no formato de projeto e também no formato de preparação pra vestibular e olimpíadas, desde que fique bem claro e segregado o que trabalhar, como trabalhar e quando trabalhar em cada formato, pois creio que seja inviável tentar fazer tudo ao mesmo tempo | J7: B1-B2 (intermediário) | L7: 30 | M7: 5.0974138 | N7: 27 | O7: 3.06875 | P7: 2.1666667 | Q7: 3.4166667 | R7: 4.5 | S7: 3.9166667 | T7: 27 | U7: 6.5294118 | V7: 6.5 | W7: 1.7 | X7: 3.3 | Y7: EMEFAF | AB7: Gosto muito de utilizar metodologías ativas, e particularmente gosto muito da sala de aula invertida, o qual eu vejo uma aplicação e envolvimento grande da sala de aula, e também trabalhar projetos de maneira interdisciplinar. | AC7: 6 | AD7: 4 | AE7: 8 | AF7: 6 | AG7: 6.05 | AH7: Vou falar o que ocorre particularmente durante a sala de aula invertida . Durante esse processo, consigo passar de grupo em grupo escutando e observando a aplicação dedicação e envolvimento deles, durante a apresentação do trabalho e quando os grupos aplicam e criam atividades avaliativa em seis colegas consigo mensurar e perceber mais ainda como estão em seu engajamento e envolvimento no processo E no final realizo uma autoavaliação com a turma de maneira individual | AI7: 2 | AJ7: 5 | AK7: 12 | AL7: 13 | AM7: 6.125 | AN7: A importância de estudar pouco a pouco diariamente e a importância da constância de elaborar os processos , e que no final serão totalmente satisfatório. Trago para a turma e explico os passos que a sala de aula invertida vai de encontro com a técnica de estudo de Feynman o qual vejo ser bem eficaz e eficiente. | AO7: 6 | AP7: 23 | AQ7: 14 | AR7: 10 | AS7: 10.65 | AT7: Gosto de estudar e aprofundar em Neurociência, técnicas de estudos e metodologias ativas, procurando trazer uma educação que tenha significado e aplicabilidade na maioria das vezes, porque as vezes em matemática temos que aprender e desenvolver alguns conceitos que no início não tenha uma aplicação tão clara e direta para as turmas, mas sempre que possível procuro trazer isso, principalmente para desmistificar esse "bicho papão" que acham que a matemática é. E não posso deixar de citar a parte de jogos, que foi o tema de meu mestrado, mas nem sempre tenho abertura para aplicar jogos pedagógicos em sala de aula, mas quando tenho eu os uso | AU7: 12 | AV7: 9 | AW7: 20 | AX7: 18 | AY7: 14 | BB7: 9 | BC7: 4 | BD7: 4 | BE7: 0 | BF7: 2 | BG7: 2 | BH7: 15 | BI7: 6 | BJ7: 10 | BK7: 1 | BL7: 4.5 | BM7: 4 | BN7: 6 | BO7: 2.5 | BP7: 4 | BQ7: 2.5 | BR7: 12 | BS7: 7.5 | BT7: 15 | BV7: =IFERROR(AVERAGEIF(AULAS_TESTE!$F:$F,$B7,AULAS_TESTE!G:G),"") -> 6.7941176 | BW7: =IFERROR(AVERAGEIF(AULAS_TESTE!$F:$F,$B7,AULAS_TESTE!H:H),"") -> 7.3529412 | BX7: =IFERROR(AVERAGEIF(AULAS_TESTE!$F:$F,$B7,AULAS_TESTE!I:I),"") -> 8.1764706 | BY7: =IFERROR(AVERAGEIF(AULAS_TESTE!$F:$F,$B7,AULAS_TESTE!J:J),"") -> 7.65625 | BZ7: =IFERROR(AVERAGEIF(AULAS_TESTE!$F:$F,$B7,AULAS_TESTE!K:K),"") -> 7.7333333 | CA7: =IFERROR(AVERAGEIF(AULAS_TESTE!$F:$F,$B7,AULAS_TESTE!L:L),"") -> 6.8076923 | CB7: =IFERROR(AVERAGEIF(AULAS_TESTE!$F:$F,$B7,AULAS_TESTE!M:M),"") -> 8.1176471 | CC7: =IFERROR(AVERAGEIF(AULAS_TESTE!$F:$F,$B7,AULAS_TESTE!N:N),"") -> 8.3125 | CD7: =IFERROR(AVERAGEIF(AULAS_TESTE!$F:$F,$B7,AULAS_TESTE!O:O),"") -> 7.5588235 | CE7: =IFERROR(AVERAGEIF(AULAS_TESTE!$F:$F,$B7,AULAS_TESTE!P:P),"") -> 7.6875 | CF7: =IFERROR(AVERAGEIF(AULAS_TESTE!$F:$F,$B7,AULAS_TESTE!Q:Q),"") -> 7.5 | CG7: =IFERROR(AVERAGEIF(AULAS_TESTE!$F:$F,$B7,AULAS_TESTE!R:R),"") -> 6.2727273 | CH7: =IFERROR(AVERAGEIF(AULAS_TESTE!$F:$F,$B7,AULAS_TESTE!S:S),"") -> 8.0625 | CI7: =IFERROR(AVERAGEIF(AULAS_TESTE!$F:$F,$B7,AULAS_TESTE!T:T),"") -> 7.59375
A8: 0 | B8: Nome do Candidato | C8: emaildocandidato@email.com | D8: 11999999999 | E8: Geografia | F8: https://drive.google.com/open?id=16FLkrb6nx3SXssc5S4TDIt9A-NYomsYO | G8: https://drive.google.com/open?id=1aFRmrYS9mkMCTO44SYEazT1NRTYAAoPS | H8: Experiência em escolas particulares e participação ativa em projetos, mostras culturais e saídas pedagógicas. | J8: A1-A2 (básico) | L8: 11 | M8: 6.1327586 | N8: 23 | O8: 2.5708333 | P8: 3.1666667 | Q8: 1.3333333 | R8: 2.4166667 | S8: 2.0833333 | T8: 1 | U8: 8.6470588 | V8: 9 | W8: 8.75 | X8: 8.8333333 | Y8: EMEFAF | AB8: Metodologias ativas. | AC8: 0 | AD8: 0 | AE8: 2 | AF8: 2 | AG8: 0.7 | AH8: Atividades escritas, apresentações em grupo ou individuais, desempenho em avaliações, participação em aula, anotações de caderno. | AI8: 7 | AJ8: 2 | AK8: 8 | AL8: 7 | AM8: 6.425 | AN8: Leitura e resumo de textos, análise e anotações de vídeos explicativos, anotações de caderno e correções de prova. | AO8: 13 | AP8: 11 | AQ8: 11 | AR8: 7 | AS8: 11.3 | AT8: Estou sempre estudando novas metodologias, buscando formação ( tenho 3 pós graduações na área de educação) leitura de materiais sobre educação e troca de conhecimentos com outros professores. | AU8: 18 | AV8: 3 | AW8: 8 | AX8: 9 | AY8: 12.425 | BB8: 15 | BC8: 6 | BD8: 6 | BE8: 0 | BF8: 4 | BG8: 5 | BH8: 15 | BI8: 8 | BJ8: 8 | BK8: 0.5 | BL8: 7.5 | BM8: 10 | BN8: 15 | BO8: 2 | BP8: 5 | BQ8: 2.5 | BR8: 15 | BS8: 7.5 | BT8: 15 | BV8: =IFERROR(AVERAGEIF(AULAS_TESTE!$F:$F,$B8,AULAS_TESTE!G:G),"") -> 6.7941176 | BW8: =IFERROR(AVERAGEIF(AULAS_TESTE!$F:$F,$B8,AULAS_TESTE!H:H),"") -> 7.3529412 | BX8: =IFERROR(AVERAGEIF(AULAS_TESTE!$F:$F,$B8,AULAS_TESTE!I:I),"") -> 8.1764706 | BY8: =IFERROR(AVERAGEIF(AULAS_TESTE!$F:$F,$B8,AULAS_TESTE!J:J),"") -> 7.65625 | BZ8: =IFERROR(AVERAGEIF(AULAS_TESTE!$F:$F,$B8,AULAS_TESTE!K:K),"") -> 7.7333333 | CA8: =IFERROR(AVERAGEIF(AULAS_TESTE!$F:$F,$B8,AULAS_TESTE!L:L),"") -> 6.8076923 | CB8: =IFERROR(AVERAGEIF(AULAS_TESTE!$F:$F,$B8,AULAS_TESTE!M:M),"") -> 8.1176471 | CC8: =IFERROR(AVERAGEIF(AULAS_TESTE!$F:$F,$B8,AULAS_TESTE!N:N),"") -> 8.3125 | CD8: =IFERROR(AVERAGEIF(AULAS_TESTE!$F:$F,$B8,AULAS_TESTE!O:O),"") -> 7.5588235 | CE8: =IFERROR(AVERAGEIF(AULAS_TESTE!$F:$F,$B8,AULAS_TESTE!P:P),"") -> 7.6875 | CF8: =IFERROR(AVERAGEIF(AULAS_TESTE!$F:$F,$B8,AULAS_TESTE!Q:Q),"") -> 7.5 | CG8: =IFERROR(AVERAGEIF(AULAS_TESTE!$F:$F,$B8,AULAS_TESTE!R:R),"") -> 6.2727273 | CH8: =IFERROR(AVERAGEIF(AULAS_TESTE!$F:$F,$B8,AULAS_TESTE!S:S),"") -> 8.0625 | CI8: =IFERROR(AVERAGEIF(AULAS_TESTE!$F:$F,$B8,AULAS_TESTE!T:T),"") -> 7.59375
A9: 0 | B9: Nome do Candidato | C9: emaildocandidato@email.com | D9: 11999999999 | E9: Matemática | F9: https://drive.google.com/open?id=1vpLGLgpviG0QOh5LPBdixePdOr1dusv_ | G9: https://drive.google.com/open?id=1NZXBUKEnUaQi5DliehTzRzRZs7AdfrcO | J9: C1-C2 (avançado/fluente) | L9: 1 | M9: 7.7560345 | N9: 1 | O9: 8.3270833 | P9: 8.6666667 | Q9: 8.25 | R9: 8.5833333 | S9: 7.1666667 | T9: 18 | U9: 7.3529412 | V9: 8 | W9: 6.4 | X9: 6.9333333 | Y9: EMEFAF | AB9: Organizo as aulas com planejamento detalhado, dividindo o tempo entre revisão, explicação teórica, resolução de exemplos e prática guiada. Uso cronogramas visuais no quadro para orientar os alunos sobre cada etapa, preparo materiais antecipadamente e aplico atividades em dupla ou grupos para agilizar a troca de ideias. Também incorporo avaliações diagnósticas rápidas para ajustar o ritmo e garantir que todos avancem sem desperdício de tempo. | AC9: 26 | AD9: 22 | AE9: 25 | AF9: 20 | AG9: 24.175 | AH9: Utilizo avaliações formativas constantes, como exercícios rápidos ao final da explicação, perguntas direcionadas durante a aula, quizzes digitais e resolução de problemas no quadro pelos próprios alunos. Também proponho tarefas que exigem aplicação do conceito em situações novas, garantindo que não apenas memorizem, mas compreendam. Registro o desempenho em rubricas simples, identificando quem precisa de reforço, e faço retomadas curtas nos encontros seguintes para consolidar o aprendizado. | AI9: 27 | AJ9: 27 | AK9: 25 | AL9: 22 | AM9: 25.775 | AN9: Faço questão de ensinar os alunos a planejar o estudo com metas claras e revisões espaçadas, usar a prática de recuperação por meio de mini-testes, desenvolver anotações ativas e aplicar a técnica da autoexplicação para consolidar conceitos. Também incentivo hábitos de organização do tempo, como ciclos de estudo focados e revisões pós-provas, garantindo que eles não apenas estudem mais, mas aprendam a aprender de forma autônoma e eficaz. | AO9: 28 | AP9: 22 | AQ9: 28 | AR9: 23 | AS9: 26.225 | AT9: Busco aprimoramento por meio de cursos de formação e leituras constantes de autores como Richard Mayer, que enfatiza a organização cognitiva do conteúdo e Polya, referência na resolução estruturada de problemas matemáticos. Além disso, participo de congressos e mantenho uma prática reflexiva baseada em evidências, revisando continuamente minhas estratégias para garantir clareza, rigor e eficácia no ensino. | AU9: 23 | AV9: 28 | AW9: 25 | AX9: 21 | AY9: 23.75 | BB9: 15 | BC9: 4 | BD9: 6 | BE9: 0 | BF9: 3 | BG9: 2 | BH9: 12 | BI9: 8 | BJ9: 8 | BK9: 1.5 | BL9: 6 | BM9: 8 | BN9: 9 | BO9: 2.5 | BP9: 5 | BQ9: 2 | BR9: 12 | BS9: 6 | BT9: 15 | BV9: =IFERROR(AVERAGEIF(AULAS_TESTE!$F:$F,$B9,AULAS_TESTE!G:G),"") -> 6.7941176 | BW9: =IFERROR(AVERAGEIF(AULAS_TESTE!$F:$F,$B9,AULAS_TESTE!H:H),"") -> 7.3529412 | BX9: =IFERROR(AVERAGEIF(AULAS_TESTE!$F:$F,$B9,AULAS_TESTE!I:I),"") -> 8.1764706 | BY9: =IFERROR(AVERAGEIF(AULAS_TESTE!$F:$F,$B9,AULAS_TESTE!J:J),"") -> 7.65625 | BZ9: =IFERROR(AVERAGEIF(AULAS_TESTE!$F:$F,$B9,AULAS_TESTE!K:K),"") -> 7.7333333 | CA9: =IFERROR(AVERAGEIF(AULAS_TESTE!$F:$F,$B9,AULAS_TESTE!L:L),"") -> 6.8076923 | CB9: =IFERROR(AVERAGEIF(AULAS_TESTE!$F:$F,$B9,AULAS_TESTE!M:M),"") -> 8.1176471 | CC9: =IFERROR(AVERAGEIF(AULAS_TESTE!$F:$F,$B9,AULAS_TESTE!N:N),"") -> 8.3125 | CD9: =IFERROR(AVERAGEIF(AULAS_TESTE!$F:$F,$B9,AULAS_TESTE!O:O),"") -> 7.5588235 | CE9: =IFERROR(AVERAGEIF(AULAS_TESTE!$F:$F,$B9,AULAS_TESTE!P:P),"") -> 7.6875 | CF9: =IFERROR(AVERAGEIF(AULAS_TESTE!$F:$F,$B9,AULAS_TESTE!Q:Q),"") -> 7.5 | CG9: =IFERROR(AVERAGEIF(AULAS_TESTE!$F:$F,$B9,AULAS_TESTE!R:R),"") -> 6.2727273 | CH9: =IFERROR(AVERAGEIF(AULAS_TESTE!$F:$F,$B9,AULAS_TESTE!S:S),"") -> 8.0625 | CI9: =IFERROR(AVERAGEIF(AULAS_TESTE!$F:$F,$B9,AULAS_TESTE!T:T),"") -> 7.59375
A10: 0 | B10: Nome do Candidato | C10: emaildocandidato@email.com | D10: 11999999999 | E10: Química | F10: https://drive.google.com/open?id=1lySCUCg5ztV_Kq2-vXcA0VzUCIbnwxVp | G10: https://drive.google.com/open?id=1AiwSLzXo766CG1E2wli5XzSQSHIEwWk7 | H10: Eu lecionei como professor em disciplina da graduação na Ufabc, tenho publicações de artigos e prêmio de melhor apresentação de poster em congresso. | I10: Apesar de recente como professor tenho muita dedicação e gostaria da oportunidade para me aperfeiçoar cada vez mais. | J10: B1-B2 (intermediário) | L10: 12 | M10: 5.9508621 | N10: 14 | O10: 4.2979167 | P10: 5.1666667 | Q10: 2 | R10: 4.9166667 | S10: 3.1666667 | T10: 10 | U10: 7.1176471 | V10: 8 | Y10: EMEFAF | AB10: Sou um professor conteúdista gosto de passar conteúdo no quadro ou em slides, trazendo aspectos do cotidanos e fazendo comparações com a disciplina, utilizando meios digitais como vídeos, simuladores. A cada conteúdo coloco questões como forma de fixação para que os alunos compreendam o que estão aprendendo. | AC10: 17 | AD10: 5 | AE10: 12 | AF10: 6 | AG10: 12.4 | AH10: Através da resolução de exercícios ou utlizando métodos que eles expliquem com suas palavras o conteúdo aprendido. Posso realizar dinâmicas com experimentos, exercícios como forma de ponto extra para estimular aprendizagem. | AI10: 16 | AJ10: 7 | AK10: 16 | AL10: 11 | AM10: 13.775 | AN10: Dependendo do conteúdo abordado, posso utilizar mapas mentais ou até mesmo mini-testes como simulados de questões de vestibulares atuais para a fixação desse conteúdo, como flashcards ou jogos de memorização como em química orgânica para distinguir as funções orgâncas ou na própria inorgânica aulas experimentais sobre ácidos e bases. | AO10: 22 | AP10: 11 | AQ10: 20 | AR10: 10 | AS10: 17.9 | AT10: Eu gosto muito de sempre colocar o aluno em um protagonismo estudantil em um ambiente estimulante que tenha recursos didáticos como jogos ou meios digitais para auxiliar-lo. Com a disciplina da Química, podemos trazer experimentos para abordar o conteúdo. Sempre trazendo um ambiente também inclusivo para o aluno caso ele precise de uma abordagem diferente para ensino. | AU10: 7 | AV10: 1 | AW10: 11 | AX10: 11 | AY10: 7.5 | BB10: 15 | BC10: 6 | BD10: 6 | BE10: 0 | BF10: 2 | BG10: 3 | BH10: 9 | BI10: 6 | BJ10: 10 | BK10: 0.5 | BL10: 7.5 | BM10: 10 | BN10: 12 | BO10: 1 | BP10: 5 | BQ10: 2.5 | BR10: 3 | BS10: 7.5 | BT10: 15 | BV10: =IFERROR(AVERAGEIF(AULAS_TESTE!$F:$F,$B10,AULAS_TESTE!G:G),"") -> 6.7941176 | BW10: =IFERROR(AVERAGEIF(AULAS_TESTE!$F:$F,$B10,AULAS_TESTE!H:H),"") -> 7.3529412 | BX10: =IFERROR(AVERAGEIF(AULAS_TESTE!$F:$F,$B10,AULAS_TESTE!I:I),"") -> 8.1764706 | BY10: =IFERROR(AVERAGEIF(AULAS_TESTE!$F:$F,$B10,AULAS_TESTE!J:J),"") -> 7.65625 | BZ10: =IFERROR(AVERAGEIF(AULAS_TESTE!$F:$F,$B10,AULAS_TESTE!K:K),"") -> 7.7333333 | CA10: =IFERROR(AVERAGEIF(AULAS_TESTE!$F:$F,$B10,AULAS_TESTE!L:L),"") -> 6.8076923 | CB10: =IFERROR(AVERAGEIF(AULAS_TESTE!$F:$F,$B10,AULAS_TESTE!M:M),"") -> 8.1176471 | CC10: =IFERROR(AVERAGEIF(AULAS_TESTE!$F:$F,$B10,AULAS_TESTE!N:N),"") -> 8.3125 | CD10: =IFERROR(AVERAGEIF(AULAS_TESTE!$F:$F,$B10,AULAS_TESTE!O:O),"") -> 7.5588235 | CE10: =IFERROR(AVERAGEIF(AULAS_TESTE!$F:$F,$B10,AULAS_TESTE!P:P),"") -> 7.6875 | CF10: =IFERROR(AVERAGEIF(AULAS_TESTE!$F:$F,$B10,AULAS_TESTE!Q:Q),"") -> 7.5 | CG10: =IFERROR(AVERAGEIF(AULAS_TESTE!$F:$F,$B10,AULAS_TESTE!R:R),"") -> 6.2727273 | CH10: =IFERROR(AVERAGEIF(AULAS_TESTE!$F:$F,$B10,AULAS_TESTE!S:S),"") -> 8.0625 | CI10: =IFERROR(AVERAGEIF(AULAS_TESTE!$F:$F,$B10,AULAS_TESTE!T:T),"") -> 7.59375
A11: 0 | B11: Nome do Candidato | C11: emaildocandidato@email.com | D11: 11999999999 | E11: Química | F11: https://drive.google.com/open?id=1lySCUCg5ztV_Kq2-vXcA0VzUCIbnwxVp | G11: https://drive.google.com/open?id=1AiwSLzXo766CG1E2wli5XzSQSHIEwWk7 | H11: Eu lecionei como professor em disciplina da graduação na Ufabc, tenho publicações de artigos e prêmio de melhor apresentação de poster em congresso. | I11: Apesar de recente como professor tenho muita dedicação e gostaria da oportunidade para me aperfeiçoar cada vez mais. | J11: B1-B2 (intermediário) | L11: 11 | M11: 5.9560345 | N11: 13 | O11: 4.3104167 | P11: 5.1666667 | Q11: 2.0833333 | R11: 4.9166667 | S11: 3.1666667 | T11: 10 | U11: 7.1176471 | V11: 8 | Y11: EMEFAF | AB11: Sou um professor conteúdista gosto de passar conteúdo no quadro ou em slides, trazendo aspectos do cotidanos e fazendo comparações com a disciplina, utilizando meios digitais como vídeos, simuladores. A cada conteúdo coloco questões como forma de fixação para que os alunos compreendam o que estão aprendendo. | AC11: 17 | AD11: 5 | AE11: 12 | AF11: 6 | AG11: 12.4 | AH11: Através da resolução de exercícios ou utlizando métodos que eles expliquem com suas palavras o conteúdo aprendido. Posso realizar dinâmicas com experimentos, exercícios como forma de ponto extra para estimular aprendizagem. | AI11: 16 | AJ11: 8 | AK11: 16 | AL11: 11 | AM11: 13.925 | AN11: Dependendo do conteúdo abordado, posso utilizar mapas mentais ou até mesmo mini-testes como simulados de questões de vestibulares atuais para a fixação desse conteúdo, como flashcards ou jogos de memorização como em química orgânica para distinguir as funções orgâncas ou na própria inorgânica aulas experimentais sobre ácidos e bases. | AO11: 22 | AP11: 11 | AQ11: 20 | AR11: 10 | AS11: 17.9 | AT11: Eu gosto muito de sempre colocar o aluno em um protagonismo estudantil em um ambiente estimulante que tenha recursos didáticos como jogos ou meios digitais para auxiliar-lo. Com a disciplina da Química, podemos trazer experimentos para abordar o conteúdo. Sempre trazendo um ambiente também inclusivo para o aluno caso ele precise de uma abordagem diferente para ensino. | AU11: 7 | AV11: 1 | AW11: 11 | AX11: 11 | AY11: 7.5 | BB11: 15 | BC11: 6 | BD11: 6 | BE11: 0 | BF11: 2 | BG11: 3 | BH11: 9 | BI11: 6 | BJ11: 10 | BK11: 0.5 | BL11: 7.5 | BM11: 10 | BN11: 12 | BO11: 1 | BP11: 5 | BQ11: 2.5 | BR11: 3 | BS11: 7.5 | BT11: 15 | BV11: =IFERROR(AVERAGEIF(AULAS_TESTE!$F:$F,$B11,AULAS_TESTE!G:G),"") -> 6.7941176 | BW11: =IFERROR(AVERAGEIF(AULAS_TESTE!$F:$F,$B11,AULAS_TESTE!H:H),"") -> 7.3529412 | BX11: =IFERROR(AVERAGEIF(AULAS_TESTE!$F:$F,$B11,AULAS_TESTE!I:I),"") -> 8.1764706 | BY11: =IFERROR(AVERAGEIF(AULAS_TESTE!$F:$F,$B11,AULAS_TESTE!J:J),"") -> 7.65625 | BZ11: =IFERROR(AVERAGEIF(AULAS_TESTE!$F:$F,$B11,AULAS_TESTE!K:K),"") -> 7.7333333 | CA11: =IFERROR(AVERAGEIF(AULAS_TESTE!$F:$F,$B11,AULAS_TESTE!L:L),"") -> 6.8076923 | CB11: =IFERROR(AVERAGEIF(AULAS_TESTE!$F:$F,$B11,AULAS_TESTE!M:M),"") -> 8.1176471 | CC11: =IFERROR(AVERAGEIF(AULAS_TESTE!$F:$F,$B11,AULAS_TESTE!N:N),"") -> 8.3125 | CD11: =IFERROR(AVERAGEIF(AULAS_TESTE!$F:$F,$B11,AULAS_TESTE!O:O),"") -> 7.5588235 | CE11: =IFERROR(AVERAGEIF(AULAS_TESTE!$F:$F,$B11,AULAS_TESTE!P:P),"") -> 7.6875 | CF11: =IFERROR(AVERAGEIF(AULAS_TESTE!$F:$F,$B11,AULAS_TESTE!Q:Q),"") -> 7.5 | CG11: =IFERROR(AVERAGEIF(AULAS_TESTE!$F:$F,$B11,AULAS_TESTE!R:R),"") -> 6.2727273 | CH11: =IFERROR(AVERAGEIF(AULAS_TESTE!$F:$F,$B11,AULAS_TESTE!S:S),"") -> 8.0625 | CI11: =IFERROR(AVERAGEIF(AULAS_TESTE!$F:$F,$B11,AULAS_TESTE!T:T),"") -> 7.59375
A12: 0 | B12: Nome do Candidato | C12: emaildocandidato@email.com | D12: 11999999999 | E12: História | F12: https://drive.google.com/open?id=1ubUAlZW66DEIUYjh3--IbyrU9zQ0lCy3 | G12: https://drive.google.com/open?id=1Dm7C84uqq5zuKKeRMrm5HRCXG88KTcwl | H12: Sou escritor, dramaturgo, fotógrafo e arte educador, já fiz também projetos em audiovisual. | J12: B1-B2 (intermediário) | L12: 41 | M12: 4.6534483 | N12: 31 | O12: 2.8708333 | P12: 2.4166667 | Q12: 2.9166667 | R12: 3.4166667 | S12: 3.5833333 | T12: 42 | U12: 5.9117647 | V12: 9 | W12: 5.5 | X12: 6.6666667 | Y12: EMEFAF | AB12: Minha estratégia de aula é a da escola humanista. Ou seja, aulas dia ligadas com usos de várias referências dentro do universo cultural dos alunos (cultura pop, poesia, música etc) de modo a dialogar o conhecimento histórico com a atualidade. A partir desse diálogo preparo questões - a maioria discursivas - para entrega na aula seguinte e começamos a partir delas. | AC12: 4 | AD12: 4 | AE12: 8 | AF12: 6 | AG12: 5.05 | AH12: Dentro de uma proposta de ensino humanista de história há várias formas de avaliação: tem os seminários, no qual eu dou um tema para ser desenvolvido, mas a partir de uma pergunta problema, na qual eu busco ver como o grupo se coordenou, que fontes usou, o trabalho escrito, e a conclusão. E tem a avaliação escrita na qual eu sempre priorizo questões discursivas, pois entendo que o verbalizar apropria melhor os caminhos do saber. | AI12: 7 | AJ12: 17 | AK12: 15 | AL12: 10 | AM12: 10.425 | AN12: Interpretação de texto. Uso de fontes diversas. Análise crítica das fontes. Sensibilização artística e cultural. | AO12: 9 | AP12: 9 | AQ12: 7 | AR12: 13 | AS12: 9.35 | AT12: Além de professor de História, sou ator, dramaturgo, fotógrafo e escritor. Em resumo, eu vivo imerso no mundo das artes e estou me especializando em arte educação. Nesse sentido, acredito que os saberes estéticos são outras formas de criação de conhecimento - a ficção científica tá aí pra nos mostrar -, muito do que hoje chamamos filosofia, medicina nasceram junto com a religião e com a arte, então eu procuro trazer no meu fazer docente esses elementos. Eu recito cordel, e assisto Anime com os alunos e converso com eles, escuto rap na sala de aula, samba, mas não de forma gratuita. É pra mostrar que a cultura vem pela vida e vice-versa. | AU12: 9 | AV12: 5 | AW12: 11 | AX12: 14 | AY12: 9.625 | BB12: 15 | BC12: 2 | BD12: 2 | BE12: 0 | BF12: 3 | BG12: 1 | BH12: 15 | BI12: 4 | BJ12: 8 | BK12: 1.5 | BL12: 3 | BM12: 6 | BN12: 3 | BO12: 2 | BP12: 4 | BQ12: 2.5 | BR12: 9 | BS12: 4.5 | BT12: 15 | BV12: =IFERROR(AVERAGEIF(AULAS_TESTE!$F:$F,$B12,AULAS_TESTE!G:G),"") -> 6.7941176 | BW12: =IFERROR(AVERAGEIF(AULAS_TESTE!$F:$F,$B12,AULAS_TESTE!H:H),"") -> 7.3529412 | BX12: =IFERROR(AVERAGEIF(AULAS_TESTE!$F:$F,$B12,AULAS_TESTE!I:I),"") -> 8.1764706 | BY12: =IFERROR(AVERAGEIF(AULAS_TESTE!$F:$F,$B12,AULAS_TESTE!J:J),"") -> 7.65625 | BZ12: =IFERROR(AVERAGEIF(AULAS_TESTE!$F:$F,$B12,AULAS_TESTE!K:K),"") -> 7.7333333 | CA12: =IFERROR(AVERAGEIF(AULAS_TESTE!$F:$F,$B12,AULAS_TESTE!L:L),"") -> 6.8076923 | CB12: =IFERROR(AVERAGEIF(AULAS_TESTE!$F:$F,$B12,AULAS_TESTE!M:M),"") -> 8.1176471 | CC12: =IFERROR(AVERAGEIF(AULAS_TESTE!$F:$F,$B12,AULAS_TESTE!N:N),"") -> 8.3125 | CD12: =IFERROR(AVERAGEIF(AULAS_TESTE!$F:$F,$B12,AULAS_TESTE!O:O),"") -> 7.5588235 | CE12: =IFERROR(AVERAGEIF(AULAS_TESTE!$F:$F,$B12,AULAS_TESTE!P:P),"") -> 7.6875 | CF12: =IFERROR(AVERAGEIF(AULAS_TESTE!$F:$F,$B12,AULAS_TESTE!Q:Q),"") -> 7.5 | CG12: =IFERROR(AVERAGEIF(AULAS_TESTE!$F:$F,$B12,AULAS_TESTE!R:R),"") -> 6.2727273 | CH12: =IFERROR(AVERAGEIF(AULAS_TESTE!$F:$F,$B12,AULAS_TESTE!S:S),"") -> 8.0625 | CI12: =IFERROR(AVERAGEIF(AULAS_TESTE!$F:$F,$B12,AULAS_TESTE!T:T),"") -> 7.59375
A13: 0 | B13: Nome do Candidato | C13: emaildocandidato@email.com | D13: 11999999999 | E13: História | F13: https://drive.google.com/open?id=1R1nM7FNWN2R13PWFz6Lb7S9nQXN_bseT | G13: https://drive.google.com/open?id=1gOG8Jzwx5mSZ5k7PRaVTPrXO7TW8UriI | H13: Meu conhecimento na escrita (com publicações de livros e premiações literárias) e vasta experiência com storytelling são elementos agregadores à prática do ensino, pois os utilizo para potencializar o interesse dos alunos às aulas, criando um ambiente mais agradável e voltado para um processo de ensino estimulante, interativo e interessante. Também trabalhei por um tempo considerável no mercado publicitário, aprendendo técnicas de persuasão e retenção de atenção, o que é fundamental para manter o foco de crianças e adolescentes. Já ministrei algumas palestras, experiências que me auxiliaram no desenvolvimento de melhor postura. | J13: C1-C2 (avançado/fluente) | L13: 30 | M13: 5.2896552 | N13: 19 | O13: 3.6583333 | P13: 3.5 | Q13: 3 | R13: 4.75 | S13: 3.5833333 | T13: 33 | U13: 6.4411765 | V13: 5.5 | Y13: EMEFAF | AB13: Estudar História não é simplesmente analisar o passado; é estudar o passado para compreender o presente. Por essa razão, gosto de iniciar minhas aulas trazendo questões do nosso cotidiano e suas relações com o passado a ser analisado. Isso faz com o que o passado deixe de ser tão abstrato para os alunos. A partir daí, gosto de trazer elementos muito interessantes sobre as sociedades em questão, para aguçar a curiosidade e interesse dos estudantes. Então, utilizo variações de suporte para ao compartilhamento do conteúdo, como vídeos elucidativos com meus comentários, slides, análise de documentos históricos, lousa, exercícios e afins. | AC13: 2 | AD13: 6 | AE13: 15 | AF13: 5 | AG13: 5.4 | AH13: Penso que as estratégias de aferição, assim como as de ensino, devem ser variadas – afinal, cada aluno possui potencialidades distintas. Entre essas variações, implemento apresentações em grupo, seminários, produções textuais, chamadas orais, listas de exercícios, rodadas de dúvidas, além das provas habituais. Desta forma, qualquer defasagem no conteúdo apresentado será ressaltada, e poderemos trabalhar nestes pontos específicos com mais afinco. | AI13: 10 | AJ13: 9 | AK13: 14 | AL13: 11 | AM13: 10.725 | AN13: Equilíbrio é fundamental. Não há uma fórmula específica para técnicas de estudo que funcionem com a mesma eficácia para todos os alunos. Uma de nossas missões como professores é municiar os estudantes com ferramentas que funcionem para cada um deles. As técnicas podem variar entre a criação de mapas mentais, indicação de produções audiovisuais elucidativas, anotações de palavras-chave, mnemônicos, produção de pequenas canções tendo como tema os assuntos estudados, ensino do conteúdo analisado para retenção do conhecimento, debates, diálogo constante e muitas outras. | AO13: 13 | AP13: 12 | AQ13: 14 | AR13: 12 | AS13: 12.85 | AT13: Penso que a prática é a mãe da perfeição. Técnicas que funcionem com uma turma, não necessariamente darão certo com outra. Construir um ferramental teórico é fundamental para lidar com a intensa rotina docente. Entre algumas de minhas leituras na área do ensino, estão os clássicos, como Piaget e suas técnicas de construção do conhecimento por meio da autonomia do aluno; a colaboração e o uso do conhecimento social a nosso favor, como escreveu Vygotsky; a segurança, confiança e afeto no processo do ensino, descritos por Wallon; a resolução analítica e crítica de problemas, proposta por John Dewey; e o cotidiano com cada turma como farol. | AU13: 17 | AV13: 9 | AW13: 14 | AX13: 15 | AY13: 14.925 | BB13: 12 | BC13: 8 | BD13: 4 | BE13: 0 | BF13: 3 | BG13: 1 | BH13: 12 | BI13: 4 | BJ13: 4 | BK13: 1.5 | BL13: 4.5 | BM13: 8 | BN13: 6 | BO13: 2.5 | BP13: 5 | BQ13: 2.5 | BR13: 9 | BS13: 7.5 | BT13: 15 | BV13: =IFERROR(AVERAGEIF(AULAS_TESTE!$F:$F,$B13,AULAS_TESTE!G:G),"") -> 6.7941176 | BW13: =IFERROR(AVERAGEIF(AULAS_TESTE!$F:$F,$B13,AULAS_TESTE!H:H),"") -> 7.3529412 | BX13: =IFERROR(AVERAGEIF(AULAS_TESTE!$F:$F,$B13,AULAS_TESTE!I:I),"") -> 8.1764706 | BY13: =IFERROR(AVERAGEIF(AULAS_TESTE!$F:$F,$B13,AULAS_TESTE!J:J),"") -> 7.65625 | BZ13: =IFERROR(AVERAGEIF(AULAS_TESTE!$F:$F,$B13,AULAS_TESTE!K:K),"") -> 7.7333333 | CA13: =IFERROR(AVERAGEIF(AULAS_TESTE!$F:$F,$B13,AULAS_TESTE!L:L),"") -> 6.8076923 | CB13: =IFERROR(AVERAGEIF(AULAS_TESTE!$F:$F,$B13,AULAS_TESTE!M:M),"") -> 8.1176471 | CC13: =IFERROR(AVERAGEIF(AULAS_TESTE!$F:$F,$B13,AULAS_TESTE!N:N),"") -> 8.3125 | CD13: =IFERROR(AVERAGEIF(AULAS_TESTE!$F:$F,$B13,AULAS_TESTE!O:O),"") -> 7.5588235 | CE13: =IFERROR(AVERAGEIF(AULAS_TESTE!$F:$F,$B13,AULAS_TESTE!P:P),"") -> 7.6875 | CF13: =IFERROR(AVERAGEIF(AULAS_TESTE!$F:$F,$B13,AULAS_TESTE!Q:Q),"") -> 7.5 | CG13: =IFERROR(AVERAGEIF(AULAS_TESTE!$F:$F,$B13,AULAS_TESTE!R:R),"") -> 6.2727273 | CH13: =IFERROR(AVERAGEIF(AULAS_TESTE!$F:$F,$B13,AULAS_TESTE!S:S),"") -> 8.0625 | CI13: =IFERROR(AVERAGEIF(AULAS_TESTE!$F:$F,$B13,AULAS_TESTE!T:T),"") -> 7.59375
A14: 0 | B14: Nome do Candidato | C14: emaildocandidato@email.com | D14: 11999999999 | E14: História | F14: https://drive.google.com/open?id=1V-uG6OyWmrimoZF68raEXp2Y8p1VIv14 | G14: https://drive.google.com/open?id=1VGTpuh10GBU6CTwYfg943YtDsCKXVsQq | H14: Trabalhei de 2019 até 2024 no Programa de Ensino Integral da Rede Estadual de Ensino do Estado de São Paulo. Em setembro desse ano concluo o mestrado em Filosofia. | J14: A1-A2 (básico) | L14: 18 | M14: 5.7336207 | N14: 21 | O14: 3.3979167 | P14: #VALUE! | Q14: 4.5833333 | R14: 5.5833333 | S14: 4.5833333 | T14: 13 | U14: 7.3823529 | V14: 7 | W14: 4.25 | X14: 5.1666667 | Y14: EMEFAF | AB14: Adoto planejamento detalhado das aulas, com objetivos claros e estratégias ativas que favorecem a participação dos alunos. Estruturo o tempo em etapas bem definidas — apresentação, desenvolvimento e síntese — equilibrando teoria e prática. Utilizo recursos digitais e metodologias diversificadas, como debates, estudos de caso e trabalhos em grupo, para dinamizar o processo. Também faço revisões breves e diagnósticos rápidos de aprendizagem, ajustando o ritmo quando necessário, de modo a garantir foco, engajamento e melhor aproveitamento do tempo em sala. | AC14: ?? | AD14: 16 | AE14: 15 | AF14: 16 | AH14: A avaliação deve ser contínua e realizada por meio de diferentes instrumentos, como provas, seminários, debates, atividades em estações, produções textuais, entre outros. | AI14: 9 | AJ14: 3 | AK14: 8 | AL14: 6 | AM14: 7.4 | AN14: Faço questão de ensinar técnicas de leitura ativa, como grifar palavras-chave, elaborar resumos e mapas conceituais, além de estratégias de organização, como o uso de agendas e cronogramas de estudos. Incentivo a autoavaliação contínua por meio de diários de aprendizagem e revisões periódicas, para que o aluno acompanhe seu progresso. Também promovo a metacognição, orientando-os a refletirem sobre como aprendem, a reconhecerem suas dificuldades e a ajustarem suas próprias estratégias, desenvolvendo autonomia e responsabilidade no processo de aprendizagem. | AO14: 12 | AP14: 21 | AQ14: 26 | AR14: 17 | AS14: 16.675 | AT14: Minha principal forma de renovação e aperfeiçoamento é a formação acadêmica, em especial o Mestrado em Filosofia, que amplia constantemente minhas perspectivas teóricas e pedagógicas. Busco integrar a reflexão filosófica com práticas didáticas atualizadas, explorando metodologias ativas (Perrenoud, Zabala, Moran) e recursos digitais que dinamizam a sala de aula. Além disso, estudo autores como Paulo Freire, que inspiram práticas dialógicas, e Dewey, que fundamenta a aprendizagem pela experiência. | AU14: 17 | AV14: 15 | AW14: 18 | AX14: 16 | AY14: 16.7 | BB14: 15 | BC14: 2 | BD14: 6 | BE14: 0 | BF14: 3 | BG14: 3 | BH14: 15 | BI14: 4 | BJ14: 8 | BK14: 1.5 | BL14: 7.5 | BM14: 10 | BN14: 6 | BO14: 1 | BP14: 5 | BQ14: 2.5 | BR14: 15 | BS14: 6 | BT14: 15 | BV14: =IFERROR(AVERAGEIF(AULAS_TESTE!$F:$F,$B14,AULAS_TESTE!G:G),"") -> 6.7941176 | BW14: =IFERROR(AVERAGEIF(AULAS_TESTE!$F:$F,$B14,AULAS_TESTE!H:H),"") -> 7.3529412 | BX14: =IFERROR(AVERAGEIF(AULAS_TESTE!$F:$F,$B14,AULAS_TESTE!I:I),"") -> 8.1764706 | BY14: =IFERROR(AVERAGEIF(AULAS_TESTE!$F:$F,$B14,AULAS_TESTE!J:J),"") -> 7.65625 | BZ14: =IFERROR(AVERAGEIF(AULAS_TESTE!$F:$F,$B14,AULAS_TESTE!K:K),"") -> 7.7333333 | CA14: =IFERROR(AVERAGEIF(AULAS_TESTE!$F:$F,$B14,AULAS_TESTE!L:L),"") -> 6.8076923 | CB14: =IFERROR(AVERAGEIF(AULAS_TESTE!$F:$F,$B14,AULAS_TESTE!M:M),"") -> 8.1176471 | CC14: =IFERROR(AVERAGEIF(AULAS_TESTE!$F:$F,$B14,AULAS_TESTE!N:N),"") -> 8.3125 | CD14: =IFERROR(AVERAGEIF(AULAS_TESTE!$F:$F,$B14,AULAS_TESTE!O:O),"") -> 7.5588235 | CE14: =IFERROR(AVERAGEIF(AULAS_TESTE!$F:$F,$B14,AULAS_TESTE!P:P),"") -> 7.6875 | CF14: =IFERROR(AVERAGEIF(AULAS_TESTE!$F:$F,$B14,AULAS_TESTE!Q:Q),"") -> 7.5 | CG14: =IFERROR(AVERAGEIF(AULAS_TESTE!$F:$F,$B14,AULAS_TESTE!R:R),"") -> 6.2727273 | CH14: =IFERROR(AVERAGEIF(AULAS_TESTE!$F:$F,$B14,AULAS_TESTE!S:S),"") -> 8.0625 | CI14: =IFERROR(AVERAGEIF(AULAS_TESTE!$F:$F,$B14,AULAS_TESTE!T:T),"") -> 7.59375
A15: 0 | B15: Nome do Candidato | C15: emaildocandidato@email.com | D15: 11999999999 | E15: Português (Produção e Interpretação de Texto) | F15: https://drive.google.com/open?id=12YAp6H1zHZvozwtX8TI_3BT-55glGaH5 | G15: https://drive.google.com/open?id=1xzYN9fRWNZY1Pr2Ljy4ErYx9FPEx9RzV | H15: Ter trabalhado durante a graduação superior em projeto extensionista para melhorar a escrita entre profissionais de Letras em decorrência da minha vivência como jornalista; ter trabalhado no início da implantação da Escola Viva no ES no primeiro mandato do governador Casagrande; ter podido entrevistas grandes personalidades sempre sem o uso do gravador, o que me desenvolveu um poder de síntese anotada que me ajudava muito na fruição do desenvolvimento do meu estilo textual. | J15: B1-B2 (intermediário) | L15: 24 | M15: 5.7396552 | N15: 20 | O15: 3.8291667 | P15: 3.5 | Q15: 3.75 | R15: 4.4166667 | S15: 4.25 | T15: 26 | U15: 7.0882353 | V15: 5.5 | Y15: EMEFAF | AB15: Atualmente, tenho empregado IA para avanço em tempo hábil em Literatura, além disso exploro bastante metodologias ativas como forma de envolver os alunos em torno da matéria, em especial Gramática, a parte científica da Língua Portuguesa. | AC15: 8 | AD15: 7 | AE15: 8 | AF15: 6 | AG15: 7.5 | AH15: Adoto diagnósticas para mensurar o nível de conteúdo da turma no início do ano letivo, como forma de nivelar em conformidade com a graduação alcançada, durante, com o objetivo de confirmar o aprendizado, e ao final, tendo a certeza da consolidação de conhecimento. | AI15: 9 | AJ15: 4 | AK15: 10 | AL15: 7 | AM15: 8.075 | AN15: Fichamentos de pontos chaves para garantir coesões sequenciais, por exemplo, com cartões de conjunções para facilitar o emprego de conectivos de desenvolvimento e conclusão, esquelamento-textual, para forjar a estrutura no cotidiano das aulas, e mapas mentais em aulas expositivas para que o alunado colabore com seu raciocínio próprio no desenvolvimento teórico. | AO15: 9 | AP15: 24 | AQ15: 21 | AR15: 20 | AS15: 15.275 | AT15: Inspiro-me bastante no Dr. Sírio Possenti, a partir da leitura do livro "Por que não escrever Gramática na Escola", tendo confirmação certeira de que sou um professor gramatiqueiro, e em Evanildo Bechara (em memória), que pregou: tão importante quanto os mecanismos linguísticos é a leitura de bons escritores, aproveitando vossas estruturas para comunicar bem no papel. Adoto bastante os métodos de refacções textuais a partir da fala de Bechara. | AU15: 16 | AV15: 10 | AW15: 14 | AX15: 18 | AY15: 15.1 | BB15: 15 | BC15: 2 | BD15: 2 | BE15: 0 | BF15: 1 | BG15: 5 | BH15: 15 | BI15: 2 | BJ15: 10 | BK15: 0.5 | BL15: 7.5 | BM15: 10 | BN15: 3 | BO15: 2.5 | BP15: 5 | BQ15: 2.5 | BR15: 15 | BS15: 7.5 | BT15: 15 | BV15: =IFERROR(AVERAGEIF(AULAS_TESTE!$F:$F,$B15,AULAS_TESTE!G:G),"") -> 6.7941176 | BW15: =IFERROR(AVERAGEIF(AULAS_TESTE!$F:$F,$B15,AULAS_TESTE!H:H),"") -> 7.3529412 | BX15: =IFERROR(AVERAGEIF(AULAS_TESTE!$F:$F,$B15,AULAS_TESTE!I:I),"") -> 8.1764706 | BY15: =IFERROR(AVERAGEIF(AULAS_TESTE!$F:$F,$B15,AULAS_TESTE!J:J),"") -> 7.65625 | BZ15: =IFERROR(AVERAGEIF(AULAS_TESTE!$F:$F,$B15,AULAS_TESTE!K:K),"") -> 7.7333333 | CA15: =IFERROR(AVERAGEIF(AULAS_TESTE!$F:$F,$B15,AULAS_TESTE!L:L),"") -> 6.8076923 | CB15: =IFERROR(AVERAGEIF(AULAS_TESTE!$F:$F,$B15,AULAS_TESTE!M:M),"") -> 8.1176471 | CC15: =IFERROR(AVERAGEIF(AULAS_TESTE!$F:$F,$B15,AULAS_TESTE!N:N),"") -> 8.3125 | CD15: =IFERROR(AVERAGEIF(AULAS_TESTE!$F:$F,$B15,AULAS_TESTE!O:O),"") -> 7.5588235 | CE15: =IFERROR(AVERAGEIF(AULAS_TESTE!$F:$F,$B15,AULAS_TESTE!P:P),"") -> 7.6875 | CF15: =IFERROR(AVERAGEIF(AULAS_TESTE!$F:$F,$B15,AULAS_TESTE!Q:Q),"") -> 7.5 | CG15: =IFERROR(AVERAGEIF(AULAS_TESTE!$F:$F,$B15,AULAS_TESTE!R:R),"") -> 6.2727273 | CH15: =IFERROR(AVERAGEIF(AULAS_TESTE!$F:$F,$B15,AULAS_TESTE!S:S),"") -> 8.0625 | CI15: =IFERROR(AVERAGEIF(AULAS_TESTE!$F:$F,$B15,AULAS_TESTE!T:T),"") -> 7.59375
A16: 0 | B16: Nome do Candidato | C16: emaildocandidato@email.com | D16: 11999999999 | E16: Matemática | F16: https://drive.google.com/open?id=1VrvXw6AilScsfz9gQBRBhnHjnYD6j_s5 | G16: https://drive.google.com/open?id=13ho83ESHRrmtxxXp8DEAUgAkFWo0P2w2 | H16: Palestras sobre acessibilidade na educação pelo SESI | J16: C1-C2 (avançado/fluente) | L16: 12 | M16: 6.4086207 | N16: 20 | O16: 4.1541667 | P16: 3.75 | Q16: 3.9166667 | R16: 5.3333333 | S16: 4.3333333 | T16: 2 | U16: 8 | Y16: EMEFAF | AB16: Quando há material didático adotado pela escola me apoio nele ao realizar um bom planejamento. Quando a escola decide não adotar um material didático, utilizo slides autorais e listas de atividades. Priorizo que os exercícios de fixação estejam divididos entre aula e casa e as situações problemas sejam realizadas majoritariamente em aula. Isso faz com que as dúvidas estejam solucionadas antes dos períodos de prova. | AC16: 9 | AD16: 9 | AE16: 12 | AF16: 11 | AG16: 9.875 | AH16: Defino pelo menos 3 etapas de avaliações formais de acordo com o estabelecido com a gestão escolar diagnóstica (geralmente uma atividade escrita com pontos extras com uma pontuação propositalmente baixa); uma avaliação parcial e uma avaliação final. Além disso, ao longo do trimestre ou bimestre realizo atividades como mapas mentais, resumos, atividades que façam os alunos explicarem seus aprendizados e isso nortea o processo avaliativo. | AI16: 19 | AJ16: 13 | AK16: 15 | AL16: 15 | AM16: 16.7 | AN16: Técnica de soluções de problemas matemáticos, reviso isso em todas as salas pelo menos uma vez no ano. É uma técnica voltada para concurseiros e vestibulandos, mas adaptável para o ensino fundamental I I faz com que o desenvolvimento das crianças cresça bastante. Além de estimular a melhora em outros conteúdos. Consiste em analisar itens e interpretar o problema antes de iniciar as contas. Observar se é ou não uma questão com "pegadinha" e qual a melhor forma de responder ou executar o que se pede. Também gosto muito de trabalhar de forma pontual aprendizagem significativa com eles, trazendo o mundo deles para a sala de aula. | AO16: 8 | AP16: 18 | AQ16: 21 | AR16: 14 | AS16: 12.825 | AT16: Isso depende das condições de trabalho, não acredito que determinada teoria de aprendizagem seja melhor do que outra, mas as escolas tem prioridades e públicos distintos. Como profissional da educação já trabalhei com ABP ou PBL (aprendizagem baseada em projetos); com a abordagem de Reggio Emília; com abordagem montessoriana para pessoas com deficiência; com acessibilidade atitudinal da Renders; com aprendizagem significativa; com aprendizagem visível do John Hatite; Sendo o mais importante e minha prioridade o respeito as crianças durante esse momento de desenvolvimento delas. | AU16: 9 | AV16: 7 | AW16: 16 | AX16: 12 | AY16: 10.45 | BB16: 15 | BC16: 4 | BD16: 6 | BE16: 0 | BF16: 3 | BG16: 2 | BH16: 15 | BI16: 6 | BJ16: 8 | BK16: 1.5 | BL16: 6 | BM16: 10 | BN16: 15 | BO16: 2.5 | BP16: 5 | BQ16: 2.5 | BR16: 12 | BS16: 7.5 | BT16: 15 | BV16: =IFERROR(AVERAGEIF(AULAS_TESTE!$F:$F,$B16,AULAS_TESTE!G:G),"") -> 6.7941176 | BW16: =IFERROR(AVERAGEIF(AULAS_TESTE!$F:$F,$B16,AULAS_TESTE!H:H),"") -> 7.3529412 | BX16: =IFERROR(AVERAGEIF(AULAS_TESTE!$F:$F,$B16,AULAS_TESTE!I:I),"") -> 8.1764706 | BY16: =IFERROR(AVERAGEIF(AULAS_TESTE!$F:$F,$B16,AULAS_TESTE!J:J),"") -> 7.65625 | BZ16: =IFERROR(AVERAGEIF(AULAS_TESTE!$F:$F,$B16,AULAS_TESTE!K:K),"") -> 7.7333333 | CA16: =IFERROR(AVERAGEIF(AULAS_TESTE!$F:$F,$B16,AULAS_TESTE!L:L),"") -> 6.8076923 | CB16: =IFERROR(AVERAGEIF(AULAS_TESTE!$F:$F,$B16,AULAS_TESTE!M:M),"") -> 8.1176471 | CC16: =IFERROR(AVERAGEIF(AULAS_TESTE!$F:$F,$B16,AULAS_TESTE!N:N),"") -> 8.3125 | CD16: =IFERROR(AVERAGEIF(AULAS_TESTE!$F:$F,$B16,AULAS_TESTE!O:O),"") -> 7.5588235 | CE16: =IFERROR(AVERAGEIF(AULAS_TESTE!$F:$F,$B16,AULAS_TESTE!P:P),"") -> 7.6875 | CF16: =IFERROR(AVERAGEIF(AULAS_TESTE!$F:$F,$B16,AULAS_TESTE!Q:Q),"") -> 7.5 | CG16: =IFERROR(AVERAGEIF(AULAS_TESTE!$F:$F,$B16,AULAS_TESTE!R:R),"") -> 6.2727273 | CH16: =IFERROR(AVERAGEIF(AULAS_TESTE!$F:$F,$B16,AULAS_TESTE!S:S),"") -> 8.0625 | CI16: =IFERROR(AVERAGEIF(AULAS_TESTE!$F:$F,$B16,AULAS_TESTE!T:T),"") -> 7.59375
